Test!!
WARNING 2024-03-24 14:14:51,515 views Homepage was accessed
WARNING 2024-03-24 14:21:43,818 views Homepage was accessed
WARNING 2024-03-24 14:22:20,879 views Homepage was accessed
ERROR 2024-03-24 15:16:42,330 log Internal Server Error: /blog/mail/
Traceback (most recent call last):
  File "/Users/shanmuganathans/opt/anaconda3/lib/python3.9/site-packages/django/core/handlers/exception.py", line 56, in inner
    response = get_response(request)
  File "/Users/shanmuganathans/opt/anaconda3/lib/python3.9/site-packages/django/core/handlers/base.py", line 197, in _get_response
    response = wrapped_callback(request, *callback_args, **callback_kwargs)
  File "/Users/shanmuganathans/Documents/Repo/Django_blog/django_project/blog/views.py", line 88, in send_email_view
    send_mail(
  File "/Users/shanmuganathans/opt/anaconda3/lib/python3.9/site-packages/django/core/mail/__init__.py", line 76, in send_mail
    connection = connection or get_connection(
  File "/Users/shanmuganathans/opt/anaconda3/lib/python3.9/site-packages/django/core/mail/__init__.py", line 50, in get_connection
    klass = import_string(backend or settings.EMAIL_BACKEND)
  File "/Users/shanmuganathans/opt/anaconda3/lib/python3.9/site-packages/django/utils/module_loading.py", line 30, in import_string
    return cached_import(module_path, class_name)
  File "/Users/shanmuganathans/opt/anaconda3/lib/python3.9/site-packages/django/utils/module_loading.py", line 15, in cached_import
    module = import_module(module_path)
  File "/Users/shanmuganathans/opt/anaconda3/lib/python3.9/importlib/__init__.py", line 127, in import_module
    return _bootstrap._gcd_import(name[level:], package, level)
  File "<frozen importlib._bootstrap>", line 1030, in _gcd_import
  File "<frozen importlib._bootstrap>", line 1007, in _find_and_load
  File "<frozen importlib._bootstrap>", line 972, in _find_and_load_unlocked
  File "<frozen importlib._bootstrap>", line 228, in _call_with_frames_removed
  File "<frozen importlib._bootstrap>", line 1030, in _gcd_import
  File "<frozen importlib._bootstrap>", line 1007, in _find_and_load
  File "<frozen importlib._bootstrap>", line 972, in _find_and_load_unlocked
  File "<frozen importlib._bootstrap>", line 228, in _call_with_frames_removed
  File "<frozen importlib._bootstrap>", line 1030, in _gcd_import
  File "<frozen importlib._bootstrap>", line 1007, in _find_and_load
  File "<frozen importlib._bootstrap>", line 984, in _find_and_load_unlocked
ModuleNotFoundError: No module named 'live'
ERROR 2024-03-24 15:17:42,100 log Internal Server Error: /blog/mail/
Traceback (most recent call last):
  File "/Users/shanmuganathans/opt/anaconda3/lib/python3.9/site-packages/django/core/handlers/exception.py", line 56, in inner
    response = get_response(request)
  File "/Users/shanmuganathans/opt/anaconda3/lib/python3.9/site-packages/django/core/handlers/base.py", line 197, in _get_response
    response = wrapped_callback(request, *callback_args, **callback_kwargs)
  File "/Users/shanmuganathans/Documents/Repo/Django_blog/django_project/blog/views.py", line 88, in send_email_view
    send_mail(
  File "/Users/shanmuganathans/opt/anaconda3/lib/python3.9/site-packages/django/core/mail/__init__.py", line 87, in send_mail
    return mail.send()
  File "/Users/shanmuganathans/opt/anaconda3/lib/python3.9/site-packages/django/core/mail/message.py", line 298, in send
    return self.get_connection(fail_silently).send_messages([self])
  File "/Users/shanmuganathans/opt/anaconda3/lib/python3.9/site-packages/django/core/mail/backends/smtp.py", line 124, in send_messages
    new_conn_created = self.open()
  File "/Users/shanmuganathans/opt/anaconda3/lib/python3.9/site-packages/django/core/mail/backends/smtp.py", line 91, in open
    self.connection.login(self.username, self.password)
  File "/Users/shanmuganathans/opt/anaconda3/lib/python3.9/smtplib.py", line 750, in login
    raise last_exception
  File "/Users/shanmuganathans/opt/anaconda3/lib/python3.9/smtplib.py", line 739, in login
    (code, resp) = self.auth(
  File "/Users/shanmuganathans/opt/anaconda3/lib/python3.9/smtplib.py", line 662, in auth
    raise SMTPAuthenticationError(code, resp)
smtplib.SMTPAuthenticationError: (535, b'5.7.8 Authentication failed')
WARNING 2024-03-26 02:58:13,789 log Not Found: /sample
WARNING 2024-03-26 02:58:13,960 log Not Found: /favicon.ico
WARNING 2024-03-26 02:58:19,753 log Not Found: /sample/
WARNING 2024-03-26 02:58:31,960 log Not Found: /sample/humanize/
WARNING 2024-03-26 02:58:40,139 log Not Found: /humanize/
WARNING 2024-03-26 02:59:01,141 log Not Found: /humanize/
WARNING 2024-03-26 02:59:10,394 log Not Found: /humanize/
ERROR 2024-03-26 02:59:15,341 log Internal Server Error: /humanize/sample/
Traceback (most recent call last):
  File "/Users/shanmuganathans/opt/anaconda3/lib/python3.9/site-packages/django/core/handlers/exception.py", line 56, in inner
    response = get_response(request)
  File "/Users/shanmuganathans/opt/anaconda3/lib/python3.9/site-packages/django/core/handlers/base.py", line 197, in _get_response
    response = wrapped_callback(request, *callback_args, **callback_kwargs)
  File "/Users/shanmuganathans/Documents/Repo/Django_blog/django_project/humanize_example/views.py", line 11, in index
    return render(request, "humanize_example/index.html", context)
  File "/Users/shanmuganathans/opt/anaconda3/lib/python3.9/site-packages/django/shortcuts.py", line 24, in render
    content = loader.render_to_string(template_name, context, request, using=using)
  File "/Users/shanmuganathans/opt/anaconda3/lib/python3.9/site-packages/django/template/loader.py", line 61, in render_to_string
    template = get_template(template_name, using=using)
  File "/Users/shanmuganathans/opt/anaconda3/lib/python3.9/site-packages/django/template/loader.py", line 15, in get_template
    return engine.get_template(template_name)
  File "/Users/shanmuganathans/opt/anaconda3/lib/python3.9/site-packages/django/template/backends/django.py", line 33, in get_template
    return Template(self.engine.get_template(template_name), self)
  File "/Users/shanmuganathans/opt/anaconda3/lib/python3.9/site-packages/django/template/engine.py", line 175, in get_template
    template, origin = self.find_template(template_name)
  File "/Users/shanmuganathans/opt/anaconda3/lib/python3.9/site-packages/django/template/engine.py", line 157, in find_template
    template = loader.get_template(name, skip=skip)
  File "/Users/shanmuganathans/opt/anaconda3/lib/python3.9/site-packages/django/template/loaders/cached.py", line 57, in get_template
    template = super().get_template(template_name, skip)
  File "/Users/shanmuganathans/opt/anaconda3/lib/python3.9/site-packages/django/template/loaders/base.py", line 28, in get_template
    return Template(
  File "/Users/shanmuganathans/opt/anaconda3/lib/python3.9/site-packages/django/template/base.py", line 154, in __init__
    self.nodelist = self.compile_nodelist()
  File "/Users/shanmuganathans/opt/anaconda3/lib/python3.9/site-packages/django/template/base.py", line 200, in compile_nodelist
    return parser.parse()
  File "/Users/shanmuganathans/opt/anaconda3/lib/python3.9/site-packages/django/template/base.py", line 484, in parse
    raise self.error(token, e)
  File "/Users/shanmuganathans/opt/anaconda3/lib/python3.9/site-packages/django/template/base.py", line 482, in parse
    filter_expression = self.compile_filter(token.contents)
  File "/Users/shanmuganathans/opt/anaconda3/lib/python3.9/site-packages/django/template/base.py", line 600, in compile_filter
    return FilterExpression(token, self)
  File "/Users/shanmuganathans/opt/anaconda3/lib/python3.9/site-packages/django/template/base.py", line 698, in __init__
    filter_func = parser.find_filter(filter_name)
  File "/Users/shanmuganathans/opt/anaconda3/lib/python3.9/site-packages/django/template/base.py", line 606, in find_filter
    raise TemplateSyntaxError("Invalid filter: '%s'" % filter_name)
django.template.exceptions.TemplateSyntaxError: Invalid filter: 'intcomma'
ERROR 2024-03-26 03:09:26,633 log Internal Server Error: /humanize/sample/
Traceback (most recent call last):
  File "/Users/shanmuganathans/opt/anaconda3/lib/python3.9/site-packages/django/core/handlers/exception.py", line 56, in inner
    response = get_response(request)
  File "/Users/shanmuganathans/opt/anaconda3/lib/python3.9/site-packages/django/core/handlers/base.py", line 197, in _get_response
    response = wrapped_callback(request, *callback_args, **callback_kwargs)
  File "/Users/shanmuganathans/Documents/Repo/Django_blog/django_project/humanize_example/views.py", line 18, in index
    return render(request, "humanize_example/index.html", context)
  File "/Users/shanmuganathans/opt/anaconda3/lib/python3.9/site-packages/django/shortcuts.py", line 24, in render
    content = loader.render_to_string(template_name, context, request, using=using)
  File "/Users/shanmuganathans/opt/anaconda3/lib/python3.9/site-packages/django/template/loader.py", line 62, in render_to_string
    return template.render(context, request)
  File "/Users/shanmuganathans/opt/anaconda3/lib/python3.9/site-packages/django/template/backends/django.py", line 61, in render
    return self.template.render(context)
  File "/Users/shanmuganathans/opt/anaconda3/lib/python3.9/site-packages/django/template/base.py", line 175, in render
    return self._render(context)
  File "/Users/shanmuganathans/opt/anaconda3/lib/python3.9/site-packages/django/template/base.py", line 167, in _render
    return self.nodelist.render(context)
  File "/Users/shanmuganathans/opt/anaconda3/lib/python3.9/site-packages/django/template/base.py", line 1005, in render
    return SafeString("".join([node.render_annotated(context) for node in self]))
  File "/Users/shanmuganathans/opt/anaconda3/lib/python3.9/site-packages/django/template/base.py", line 1005, in <listcomp>
    return SafeString("".join([node.render_annotated(context) for node in self]))
  File "/Users/shanmuganathans/opt/anaconda3/lib/python3.9/site-packages/django/template/base.py", line 966, in render_annotated
    return self.render(context)
  File "/Users/shanmuganathans/opt/anaconda3/lib/python3.9/site-packages/django/template/base.py", line 1064, in render
    output = self.filter_expression.resolve(context)
  File "/Users/shanmuganathans/opt/anaconda3/lib/python3.9/site-packages/django/template/base.py", line 742, in resolve
    new_obj = func(obj, *arg_vals)
  File "/Users/shanmuganathans/opt/anaconda3/lib/python3.9/site-packages/django/contrib/humanize/templatetags/humanize.py", line 204, in naturaltime
    return NaturalTimeFormatter.string_for(value)
  File "/Users/shanmuganathans/opt/anaconda3/lib/python3.9/site-packages/django/contrib/humanize/templatetags/humanize.py", line 286, in string_for
    now = datetime.now(timezone.utc if is_aware(value) else None)
  File "/Users/shanmuganathans/opt/anaconda3/lib/python3.9/site-packages/django/utils/timezone.py", line 256, in is_aware
    return value.utcoffset() is not None
AttributeError: 'datetime.date' object has no attribute 'utcoffset'
ERROR 2024-03-26 03:13:54,787 log Internal Server Error: /humanize/sample/
Traceback (most recent call last):
  File "/Users/shanmuganathans/opt/anaconda3/lib/python3.9/site-packages/django/core/handlers/exception.py", line 56, in inner
    response = get_response(request)
  File "/Users/shanmuganathans/opt/anaconda3/lib/python3.9/site-packages/django/core/handlers/base.py", line 197, in _get_response
    response = wrapped_callback(request, *callback_args, **callback_kwargs)
  File "/Users/shanmuganathans/Documents/Repo/Django_blog/django_project/humanize_example/views.py", line 18, in index
    return render(request, "humanize_example/index.html", context)
  File "/Users/shanmuganathans/opt/anaconda3/lib/python3.9/site-packages/django/shortcuts.py", line 24, in render
    content = loader.render_to_string(template_name, context, request, using=using)
  File "/Users/shanmuganathans/opt/anaconda3/lib/python3.9/site-packages/django/template/loader.py", line 62, in render_to_string
    return template.render(context, request)
  File "/Users/shanmuganathans/opt/anaconda3/lib/python3.9/site-packages/django/template/backends/django.py", line 61, in render
    return self.template.render(context)
  File "/Users/shanmuganathans/opt/anaconda3/lib/python3.9/site-packages/django/template/base.py", line 175, in render
    return self._render(context)
  File "/Users/shanmuganathans/opt/anaconda3/lib/python3.9/site-packages/django/template/base.py", line 167, in _render
    return self.nodelist.render(context)
  File "/Users/shanmuganathans/opt/anaconda3/lib/python3.9/site-packages/django/template/base.py", line 1005, in render
    return SafeString("".join([node.render_annotated(context) for node in self]))
  File "/Users/shanmuganathans/opt/anaconda3/lib/python3.9/site-packages/django/template/base.py", line 1005, in <listcomp>
    return SafeString("".join([node.render_annotated(context) for node in self]))
  File "/Users/shanmuganathans/opt/anaconda3/lib/python3.9/site-packages/django/template/base.py", line 966, in render_annotated
    return self.render(context)
  File "/Users/shanmuganathans/opt/anaconda3/lib/python3.9/site-packages/django/template/base.py", line 1064, in render
    output = self.filter_expression.resolve(context)
  File "/Users/shanmuganathans/opt/anaconda3/lib/python3.9/site-packages/django/template/base.py", line 742, in resolve
    new_obj = func(obj, *arg_vals)
  File "/Users/shanmuganathans/opt/anaconda3/lib/python3.9/site-packages/django/contrib/humanize/templatetags/humanize.py", line 204, in naturaltime
    return NaturalTimeFormatter.string_for(value)
  File "/Users/shanmuganathans/opt/anaconda3/lib/python3.9/site-packages/django/contrib/humanize/templatetags/humanize.py", line 286, in string_for
    now = datetime.now(timezone.utc if is_aware(value) else None)
  File "/Users/shanmuganathans/opt/anaconda3/lib/python3.9/site-packages/django/utils/timezone.py", line 256, in is_aware
    return value.utcoffset() is not None
AttributeError: 'datetime.date' object has no attribute 'utcoffset'
ERROR 2024-03-26 03:13:55,729 log Internal Server Error: /humanize/sample/
Traceback (most recent call last):
  File "/Users/shanmuganathans/opt/anaconda3/lib/python3.9/site-packages/django/core/handlers/exception.py", line 56, in inner
    response = get_response(request)
  File "/Users/shanmuganathans/opt/anaconda3/lib/python3.9/site-packages/django/core/handlers/base.py", line 197, in _get_response
    response = wrapped_callback(request, *callback_args, **callback_kwargs)
  File "/Users/shanmuganathans/Documents/Repo/Django_blog/django_project/humanize_example/views.py", line 18, in index
    return render(request, "humanize_example/index.html", context)
  File "/Users/shanmuganathans/opt/anaconda3/lib/python3.9/site-packages/django/shortcuts.py", line 24, in render
    content = loader.render_to_string(template_name, context, request, using=using)
  File "/Users/shanmuganathans/opt/anaconda3/lib/python3.9/site-packages/django/template/loader.py", line 62, in render_to_string
    return template.render(context, request)
  File "/Users/shanmuganathans/opt/anaconda3/lib/python3.9/site-packages/django/template/backends/django.py", line 61, in render
    return self.template.render(context)
  File "/Users/shanmuganathans/opt/anaconda3/lib/python3.9/site-packages/django/template/base.py", line 175, in render
    return self._render(context)
  File "/Users/shanmuganathans/opt/anaconda3/lib/python3.9/site-packages/django/template/base.py", line 167, in _render
    return self.nodelist.render(context)
  File "/Users/shanmuganathans/opt/anaconda3/lib/python3.9/site-packages/django/template/base.py", line 1005, in render
    return SafeString("".join([node.render_annotated(context) for node in self]))
  File "/Users/shanmuganathans/opt/anaconda3/lib/python3.9/site-packages/django/template/base.py", line 1005, in <listcomp>
    return SafeString("".join([node.render_annotated(context) for node in self]))
  File "/Users/shanmuganathans/opt/anaconda3/lib/python3.9/site-packages/django/template/base.py", line 966, in render_annotated
    return self.render(context)
  File "/Users/shanmuganathans/opt/anaconda3/lib/python3.9/site-packages/django/template/base.py", line 1064, in render
    output = self.filter_expression.resolve(context)
  File "/Users/shanmuganathans/opt/anaconda3/lib/python3.9/site-packages/django/template/base.py", line 742, in resolve
    new_obj = func(obj, *arg_vals)
  File "/Users/shanmuganathans/opt/anaconda3/lib/python3.9/site-packages/django/contrib/humanize/templatetags/humanize.py", line 204, in naturaltime
    return NaturalTimeFormatter.string_for(value)
  File "/Users/shanmuganathans/opt/anaconda3/lib/python3.9/site-packages/django/contrib/humanize/templatetags/humanize.py", line 286, in string_for
    now = datetime.now(timezone.utc if is_aware(value) else None)
  File "/Users/shanmuganathans/opt/anaconda3/lib/python3.9/site-packages/django/utils/timezone.py", line 256, in is_aware
    return value.utcoffset() is not None
AttributeError: 'datetime.date' object has no attribute 'utcoffset'
ERROR 2024-03-26 03:13:56,424 log Internal Server Error: /humanize/sample/
Traceback (most recent call last):
  File "/Users/shanmuganathans/opt/anaconda3/lib/python3.9/site-packages/django/core/handlers/exception.py", line 56, in inner
    response = get_response(request)
  File "/Users/shanmuganathans/opt/anaconda3/lib/python3.9/site-packages/django/core/handlers/base.py", line 197, in _get_response
    response = wrapped_callback(request, *callback_args, **callback_kwargs)
  File "/Users/shanmuganathans/Documents/Repo/Django_blog/django_project/humanize_example/views.py", line 18, in index
    return render(request, "humanize_example/index.html", context)
  File "/Users/shanmuganathans/opt/anaconda3/lib/python3.9/site-packages/django/shortcuts.py", line 24, in render
    content = loader.render_to_string(template_name, context, request, using=using)
  File "/Users/shanmuganathans/opt/anaconda3/lib/python3.9/site-packages/django/template/loader.py", line 62, in render_to_string
    return template.render(context, request)
  File "/Users/shanmuganathans/opt/anaconda3/lib/python3.9/site-packages/django/template/backends/django.py", line 61, in render
    return self.template.render(context)
  File "/Users/shanmuganathans/opt/anaconda3/lib/python3.9/site-packages/django/template/base.py", line 175, in render
    return self._render(context)
  File "/Users/shanmuganathans/opt/anaconda3/lib/python3.9/site-packages/django/template/base.py", line 167, in _render
    return self.nodelist.render(context)
  File "/Users/shanmuganathans/opt/anaconda3/lib/python3.9/site-packages/django/template/base.py", line 1005, in render
    return SafeString("".join([node.render_annotated(context) for node in self]))
  File "/Users/shanmuganathans/opt/anaconda3/lib/python3.9/site-packages/django/template/base.py", line 1005, in <listcomp>
    return SafeString("".join([node.render_annotated(context) for node in self]))
  File "/Users/shanmuganathans/opt/anaconda3/lib/python3.9/site-packages/django/template/base.py", line 966, in render_annotated
    return self.render(context)
  File "/Users/shanmuganathans/opt/anaconda3/lib/python3.9/site-packages/django/template/base.py", line 1064, in render
    output = self.filter_expression.resolve(context)
  File "/Users/shanmuganathans/opt/anaconda3/lib/python3.9/site-packages/django/template/base.py", line 742, in resolve
    new_obj = func(obj, *arg_vals)
  File "/Users/shanmuganathans/opt/anaconda3/lib/python3.9/site-packages/django/contrib/humanize/templatetags/humanize.py", line 204, in naturaltime
    return NaturalTimeFormatter.string_for(value)
  File "/Users/shanmuganathans/opt/anaconda3/lib/python3.9/site-packages/django/contrib/humanize/templatetags/humanize.py", line 286, in string_for
    now = datetime.now(timezone.utc if is_aware(value) else None)
  File "/Users/shanmuganathans/opt/anaconda3/lib/python3.9/site-packages/django/utils/timezone.py", line 256, in is_aware
    return value.utcoffset() is not None
AttributeError: 'datetime.date' object has no attribute 'utcoffset'
ERROR 2024-03-26 03:13:56,707 log Internal Server Error: /humanize/sample/
Traceback (most recent call last):
  File "/Users/shanmuganathans/opt/anaconda3/lib/python3.9/site-packages/django/core/handlers/exception.py", line 56, in inner
    response = get_response(request)
  File "/Users/shanmuganathans/opt/anaconda3/lib/python3.9/site-packages/django/core/handlers/base.py", line 197, in _get_response
    response = wrapped_callback(request, *callback_args, **callback_kwargs)
  File "/Users/shanmuganathans/Documents/Repo/Django_blog/django_project/humanize_example/views.py", line 18, in index
    return render(request, "humanize_example/index.html", context)
  File "/Users/shanmuganathans/opt/anaconda3/lib/python3.9/site-packages/django/shortcuts.py", line 24, in render
    content = loader.render_to_string(template_name, context, request, using=using)
  File "/Users/shanmuganathans/opt/anaconda3/lib/python3.9/site-packages/django/template/loader.py", line 62, in render_to_string
    return template.render(context, request)
  File "/Users/shanmuganathans/opt/anaconda3/lib/python3.9/site-packages/django/template/backends/django.py", line 61, in render
    return self.template.render(context)
  File "/Users/shanmuganathans/opt/anaconda3/lib/python3.9/site-packages/django/template/base.py", line 175, in render
    return self._render(context)
  File "/Users/shanmuganathans/opt/anaconda3/lib/python3.9/site-packages/django/template/base.py", line 167, in _render
    return self.nodelist.render(context)
  File "/Users/shanmuganathans/opt/anaconda3/lib/python3.9/site-packages/django/template/base.py", line 1005, in render
    return SafeString("".join([node.render_annotated(context) for node in self]))
  File "/Users/shanmuganathans/opt/anaconda3/lib/python3.9/site-packages/django/template/base.py", line 1005, in <listcomp>
    return SafeString("".join([node.render_annotated(context) for node in self]))
  File "/Users/shanmuganathans/opt/anaconda3/lib/python3.9/site-packages/django/template/base.py", line 966, in render_annotated
    return self.render(context)
  File "/Users/shanmuganathans/opt/anaconda3/lib/python3.9/site-packages/django/template/base.py", line 1064, in render
    output = self.filter_expression.resolve(context)
  File "/Users/shanmuganathans/opt/anaconda3/lib/python3.9/site-packages/django/template/base.py", line 742, in resolve
    new_obj = func(obj, *arg_vals)
  File "/Users/shanmuganathans/opt/anaconda3/lib/python3.9/site-packages/django/contrib/humanize/templatetags/humanize.py", line 204, in naturaltime
    return NaturalTimeFormatter.string_for(value)
  File "/Users/shanmuganathans/opt/anaconda3/lib/python3.9/site-packages/django/contrib/humanize/templatetags/humanize.py", line 286, in string_for
    now = datetime.now(timezone.utc if is_aware(value) else None)
  File "/Users/shanmuganathans/opt/anaconda3/lib/python3.9/site-packages/django/utils/timezone.py", line 256, in is_aware
    return value.utcoffset() is not None
AttributeError: 'datetime.date' object has no attribute 'utcoffset'
ERROR 2024-03-26 03:16:14,267 log Internal Server Error: /humanize/sample/
Traceback (most recent call last):
  File "/Users/shanmuganathans/opt/anaconda3/lib/python3.9/site-packages/django/core/handlers/exception.py", line 56, in inner
    response = get_response(request)
  File "/Users/shanmuganathans/opt/anaconda3/lib/python3.9/site-packages/django/core/handlers/base.py", line 197, in _get_response
    response = wrapped_callback(request, *callback_args, **callback_kwargs)
  File "/Users/shanmuganathans/Documents/Repo/Django_blog/django_project/humanize_example/views.py", line 15, in index
    "date_example" : d,
NameError: name 'd' is not defined
WARNING 2024-03-26 16:00:39,311 log Not Found: /accounts/login/
ERROR 2024-03-26 16:02:49,691 log Internal Server Error: /blog/mail/
Traceback (most recent call last):
  File "/Users/shanmuganathans/opt/anaconda3/lib/python3.9/site-packages/django/core/handlers/exception.py", line 56, in inner
    response = get_response(request)
  File "/Users/shanmuganathans/opt/anaconda3/lib/python3.9/site-packages/django/core/handlers/base.py", line 197, in _get_response
    response = wrapped_callback(request, *callback_args, **callback_kwargs)
  File "/Users/shanmuganathans/Documents/Repo/Django_blog/django_project/blog/views.py", line 88, in send_email_view
    send_mail(
  File "/Users/shanmuganathans/opt/anaconda3/lib/python3.9/site-packages/django/core/mail/__init__.py", line 87, in send_mail
    return mail.send()
  File "/Users/shanmuganathans/opt/anaconda3/lib/python3.9/site-packages/django/core/mail/message.py", line 298, in send
    return self.get_connection(fail_silently).send_messages([self])
  File "/Users/shanmuganathans/opt/anaconda3/lib/python3.9/site-packages/django/core/mail/backends/smtp.py", line 124, in send_messages
    new_conn_created = self.open()
  File "/Users/shanmuganathans/opt/anaconda3/lib/python3.9/site-packages/django/core/mail/backends/smtp.py", line 91, in open
    self.connection.login(self.username, self.password)
  File "/Users/shanmuganathans/opt/anaconda3/lib/python3.9/smtplib.py", line 750, in login
    raise last_exception
  File "/Users/shanmuganathans/opt/anaconda3/lib/python3.9/smtplib.py", line 739, in login
    (code, resp) = self.auth(
  File "/Users/shanmuganathans/opt/anaconda3/lib/python3.9/smtplib.py", line 662, in auth
    raise SMTPAuthenticationError(code, resp)
smtplib.SMTPAuthenticationError: (535, b'5.7.8 Username and Password not accepted. For more information, go to\n5.7.8  https://support.google.com/mail/?p=BadCredentials a2-20020a170902ecc200b001e020a47fe9sm6940259plh.261 - gsmtp')
WARNING 2024-03-27 03:08:21,082 log Not Found: /custom/
WARNING 2024-03-27 03:08:43,466 log Not Found: /custom
WARNING 2024-03-27 03:08:43,594 log Not Found: /favicon.ico
WARNING 2024-03-27 03:08:46,843 log Not Found: /custom/
WARNING 2024-03-27 03:08:59,687 log Not Found: /custom/
ERROR 2024-03-27 03:09:07,357 log Internal Server Error: /custom/example/
Traceback (most recent call last):
  File "/Users/shanmuganathans/opt/anaconda3/lib/python3.9/site-packages/django/core/handlers/exception.py", line 56, in inner
    response = get_response(request)
  File "/Users/shanmuganathans/opt/anaconda3/lib/python3.9/site-packages/django/core/handlers/base.py", line 197, in _get_response
    response = wrapped_callback(request, *callback_args, **callback_kwargs)
  File "/Users/shanmuganathans/Documents/Repo/Django_blog/django_project/custome_template_tags/views.py", line 6, in example
    return render(request, "custome_template_tags/example.html")
  File "/Users/shanmuganathans/opt/anaconda3/lib/python3.9/site-packages/django/shortcuts.py", line 24, in render
    content = loader.render_to_string(template_name, context, request, using=using)
  File "/Users/shanmuganathans/opt/anaconda3/lib/python3.9/site-packages/django/template/loader.py", line 61, in render_to_string
    template = get_template(template_name, using=using)
  File "/Users/shanmuganathans/opt/anaconda3/lib/python3.9/site-packages/django/template/loader.py", line 15, in get_template
    return engine.get_template(template_name)
  File "/Users/shanmuganathans/opt/anaconda3/lib/python3.9/site-packages/django/template/backends/django.py", line 33, in get_template
    return Template(self.engine.get_template(template_name), self)
  File "/Users/shanmuganathans/opt/anaconda3/lib/python3.9/site-packages/django/template/engine.py", line 175, in get_template
    template, origin = self.find_template(template_name)
  File "/Users/shanmuganathans/opt/anaconda3/lib/python3.9/site-packages/django/template/engine.py", line 157, in find_template
    template = loader.get_template(name, skip=skip)
  File "/Users/shanmuganathans/opt/anaconda3/lib/python3.9/site-packages/django/template/loaders/cached.py", line 57, in get_template
    template = super().get_template(template_name, skip)
  File "/Users/shanmuganathans/opt/anaconda3/lib/python3.9/site-packages/django/template/loaders/base.py", line 28, in get_template
    return Template(
  File "/Users/shanmuganathans/opt/anaconda3/lib/python3.9/site-packages/django/template/base.py", line 154, in __init__
    self.nodelist = self.compile_nodelist()
  File "/Users/shanmuganathans/opt/anaconda3/lib/python3.9/site-packages/django/template/base.py", line 200, in compile_nodelist
    return parser.parse()
  File "/Users/shanmuganathans/opt/anaconda3/lib/python3.9/site-packages/django/template/base.py", line 478, in parse
    raise self.error(
django.template.exceptions.TemplateSyntaxError: Empty variable tag on line 8
ERROR 2024-03-27 03:27:08,273 log Internal Server Error: /custom/example/
Traceback (most recent call last):
  File "/Users/shanmuganathans/opt/anaconda3/lib/python3.9/site-packages/django/core/handlers/exception.py", line 56, in inner
    response = get_response(request)
  File "/Users/shanmuganathans/opt/anaconda3/lib/python3.9/site-packages/django/core/handlers/base.py", line 197, in _get_response
    response = wrapped_callback(request, *callback_args, **callback_kwargs)
  File "/Users/shanmuganathans/Documents/Repo/Django_blog/django_project/custome_template_tags/views.py", line 6, in example
    return render(request, "custome_template_tags/example.html")
  File "/Users/shanmuganathans/opt/anaconda3/lib/python3.9/site-packages/django/shortcuts.py", line 24, in render
    content = loader.render_to_string(template_name, context, request, using=using)
  File "/Users/shanmuganathans/opt/anaconda3/lib/python3.9/site-packages/django/template/loader.py", line 61, in render_to_string
    template = get_template(template_name, using=using)
  File "/Users/shanmuganathans/opt/anaconda3/lib/python3.9/site-packages/django/template/loader.py", line 15, in get_template
    return engine.get_template(template_name)
  File "/Users/shanmuganathans/opt/anaconda3/lib/python3.9/site-packages/django/template/backends/django.py", line 33, in get_template
    return Template(self.engine.get_template(template_name), self)
  File "/Users/shanmuganathans/opt/anaconda3/lib/python3.9/site-packages/django/template/engine.py", line 175, in get_template
    template, origin = self.find_template(template_name)
  File "/Users/shanmuganathans/opt/anaconda3/lib/python3.9/site-packages/django/template/engine.py", line 157, in find_template
    template = loader.get_template(name, skip=skip)
  File "/Users/shanmuganathans/opt/anaconda3/lib/python3.9/site-packages/django/template/loaders/cached.py", line 57, in get_template
    template = super().get_template(template_name, skip)
  File "/Users/shanmuganathans/opt/anaconda3/lib/python3.9/site-packages/django/template/loaders/base.py", line 28, in get_template
    return Template(
  File "/Users/shanmuganathans/opt/anaconda3/lib/python3.9/site-packages/django/template/base.py", line 154, in __init__
    self.nodelist = self.compile_nodelist()
  File "/Users/shanmuganathans/opt/anaconda3/lib/python3.9/site-packages/django/template/base.py", line 200, in compile_nodelist
    return parser.parse()
  File "/Users/shanmuganathans/opt/anaconda3/lib/python3.9/site-packages/django/template/base.py", line 484, in parse
    raise self.error(token, e)
  File "/Users/shanmuganathans/opt/anaconda3/lib/python3.9/site-packages/django/template/base.py", line 482, in parse
    filter_expression = self.compile_filter(token.contents)
  File "/Users/shanmuganathans/opt/anaconda3/lib/python3.9/site-packages/django/template/base.py", line 600, in compile_filter
    return FilterExpression(token, self)
  File "/Users/shanmuganathans/opt/anaconda3/lib/python3.9/site-packages/django/template/base.py", line 698, in __init__
    filter_func = parser.find_filter(filter_name)
  File "/Users/shanmuganathans/opt/anaconda3/lib/python3.9/site-packages/django/template/base.py", line 606, in find_filter
    raise TemplateSyntaxError("Invalid filter: '%s'" % filter_name)
django.template.exceptions.TemplateSyntaxError: Invalid filter: 'addnum'
ERROR 2024-03-27 03:27:21,274 log Internal Server Error: /custom/example/
Traceback (most recent call last):
  File "/Users/shanmuganathans/opt/anaconda3/lib/python3.9/site-packages/django/template/base.py", line 505, in parse
    compile_func = self.tags[command]
KeyError: 'random_number1'

During handling of the above exception, another exception occurred:

Traceback (most recent call last):
  File "/Users/shanmuganathans/opt/anaconda3/lib/python3.9/site-packages/django/core/handlers/exception.py", line 56, in inner
    response = get_response(request)
  File "/Users/shanmuganathans/opt/anaconda3/lib/python3.9/site-packages/django/core/handlers/base.py", line 197, in _get_response
    response = wrapped_callback(request, *callback_args, **callback_kwargs)
  File "/Users/shanmuganathans/Documents/Repo/Django_blog/django_project/custome_template_tags/views.py", line 6, in example
    return render(request, "custome_template_tags/example.html")
  File "/Users/shanmuganathans/opt/anaconda3/lib/python3.9/site-packages/django/shortcuts.py", line 24, in render
    content = loader.render_to_string(template_name, context, request, using=using)
  File "/Users/shanmuganathans/opt/anaconda3/lib/python3.9/site-packages/django/template/loader.py", line 61, in render_to_string
    template = get_template(template_name, using=using)
  File "/Users/shanmuganathans/opt/anaconda3/lib/python3.9/site-packages/django/template/loader.py", line 15, in get_template
    return engine.get_template(template_name)
  File "/Users/shanmuganathans/opt/anaconda3/lib/python3.9/site-packages/django/template/backends/django.py", line 33, in get_template
    return Template(self.engine.get_template(template_name), self)
  File "/Users/shanmuganathans/opt/anaconda3/lib/python3.9/site-packages/django/template/engine.py", line 175, in get_template
    template, origin = self.find_template(template_name)
  File "/Users/shanmuganathans/opt/anaconda3/lib/python3.9/site-packages/django/template/engine.py", line 157, in find_template
    template = loader.get_template(name, skip=skip)
  File "/Users/shanmuganathans/opt/anaconda3/lib/python3.9/site-packages/django/template/loaders/cached.py", line 57, in get_template
    template = super().get_template(template_name, skip)
  File "/Users/shanmuganathans/opt/anaconda3/lib/python3.9/site-packages/django/template/loaders/base.py", line 28, in get_template
    return Template(
  File "/Users/shanmuganathans/opt/anaconda3/lib/python3.9/site-packages/django/template/base.py", line 154, in __init__
    self.nodelist = self.compile_nodelist()
  File "/Users/shanmuganathans/opt/anaconda3/lib/python3.9/site-packages/django/template/base.py", line 200, in compile_nodelist
    return parser.parse()
  File "/Users/shanmuganathans/opt/anaconda3/lib/python3.9/site-packages/django/template/base.py", line 507, in parse
    self.invalid_block_tag(token, command, parse_until)
  File "/Users/shanmuganathans/opt/anaconda3/lib/python3.9/site-packages/django/template/base.py", line 568, in invalid_block_tag
    raise self.error(
django.template.exceptions.TemplateSyntaxError: Invalid block tag on line 7: 'random_number1'. Did you forget to register or load this tag?
ERROR 2024-03-27 03:28:39,678 log Internal Server Error: /custom/example/
Traceback (most recent call last):
  File "/Users/shanmuganathans/opt/anaconda3/lib/python3.9/site-packages/django/core/handlers/exception.py", line 56, in inner
    response = get_response(request)
  File "/Users/shanmuganathans/opt/anaconda3/lib/python3.9/site-packages/django/core/handlers/base.py", line 197, in _get_response
    response = wrapped_callback(request, *callback_args, **callback_kwargs)
  File "/Users/shanmuganathans/Documents/Repo/Django_blog/django_project/custome_template_tags/views.py", line 6, in example
    return render(request, "custome_template_tags/example.html")
  File "/Users/shanmuganathans/opt/anaconda3/lib/python3.9/site-packages/django/shortcuts.py", line 24, in render
    content = loader.render_to_string(template_name, context, request, using=using)
  File "/Users/shanmuganathans/opt/anaconda3/lib/python3.9/site-packages/django/template/loader.py", line 62, in render_to_string
    return template.render(context, request)
  File "/Users/shanmuganathans/opt/anaconda3/lib/python3.9/site-packages/django/template/backends/django.py", line 61, in render
    return self.template.render(context)
  File "/Users/shanmuganathans/opt/anaconda3/lib/python3.9/site-packages/django/template/base.py", line 175, in render
    return self._render(context)
  File "/Users/shanmuganathans/opt/anaconda3/lib/python3.9/site-packages/django/template/base.py", line 167, in _render
    return self.nodelist.render(context)
  File "/Users/shanmuganathans/opt/anaconda3/lib/python3.9/site-packages/django/template/base.py", line 1005, in render
    return SafeString("".join([node.render_annotated(context) for node in self]))
  File "/Users/shanmuganathans/opt/anaconda3/lib/python3.9/site-packages/django/template/base.py", line 1005, in <listcomp>
    return SafeString("".join([node.render_annotated(context) for node in self]))
  File "/Users/shanmuganathans/opt/anaconda3/lib/python3.9/site-packages/django/template/base.py", line 966, in render_annotated
    return self.render(context)
  File "/Users/shanmuganathans/opt/anaconda3/lib/python3.9/site-packages/django/template/base.py", line 1064, in render
    output = self.filter_expression.resolve(context)
  File "/Users/shanmuganathans/opt/anaconda3/lib/python3.9/site-packages/django/template/base.py", line 742, in resolve
    new_obj = func(obj, *arg_vals)
  File "/Users/shanmuganathans/Documents/Repo/Django_blog/django_project/custome_template_tags/templatetags/custom_filters.py", line 11, in add
    return value+100
TypeError: can only concatenate str (not "int") to str
ERROR 2024-03-27 03:34:58,199 log Internal Server Error: /blog/mail/
Traceback (most recent call last):
  File "/Users/shanmuganathans/opt/anaconda3/lib/python3.9/site-packages/django/core/handlers/exception.py", line 56, in inner
    response = get_response(request)
  File "/Users/shanmuganathans/opt/anaconda3/lib/python3.9/site-packages/django/core/handlers/base.py", line 197, in _get_response
    response = wrapped_callback(request, *callback_args, **callback_kwargs)
  File "/Users/shanmuganathans/Documents/Repo/Django_blog/django_project/blog/views.py", line 88, in send_email_view
    send_mail(
  File "/Users/shanmuganathans/opt/anaconda3/lib/python3.9/site-packages/django/core/mail/__init__.py", line 87, in send_mail
    return mail.send()
  File "/Users/shanmuganathans/opt/anaconda3/lib/python3.9/site-packages/django/core/mail/message.py", line 298, in send
    return self.get_connection(fail_silently).send_messages([self])
  File "/Users/shanmuganathans/opt/anaconda3/lib/python3.9/site-packages/django/core/mail/backends/smtp.py", line 124, in send_messages
    new_conn_created = self.open()
  File "/Users/shanmuganathans/opt/anaconda3/lib/python3.9/site-packages/django/core/mail/backends/smtp.py", line 91, in open
    self.connection.login(self.username, self.password)
  File "/Users/shanmuganathans/opt/anaconda3/lib/python3.9/smtplib.py", line 750, in login
    raise last_exception
  File "/Users/shanmuganathans/opt/anaconda3/lib/python3.9/smtplib.py", line 739, in login
    (code, resp) = self.auth(
  File "/Users/shanmuganathans/opt/anaconda3/lib/python3.9/smtplib.py", line 662, in auth
    raise SMTPAuthenticationError(code, resp)
smtplib.SMTPAuthenticationError: (535, b'5.7.8 Username and Password not accepted. For more information, go to\n5.7.8  https://support.google.com/mail/?p=BadCredentials d6-20020a056a00198600b006e6c10bdc16sm255085pfl.85 - gsmtp')
WARNING 2024-03-27 16:34:03,407 log Not Found: /accounts/login/
WARNING 2024-03-27 16:34:03,547 log Not Found: /favicon.ico
ERROR 2024-03-27 16:34:12,949 log Internal Server Error: /blog/pagination/
Traceback (most recent call last):
  File "/Users/shanmuganathans/opt/anaconda3/lib/python3.9/site-packages/django/core/handlers/exception.py", line 56, in inner
    response = get_response(request)
  File "/Users/shanmuganathans/opt/anaconda3/lib/python3.9/site-packages/django/core/handlers/base.py", line 197, in _get_response
    response = wrapped_callback(request, *callback_args, **callback_kwargs)
  File "/Users/shanmuganathans/Documents/Repo/Django_blog/django_project/blog/views.py", line 116, in test_pagination
    return render(request, 'blog/pagination.html', {'page_obj': page_obj})
  File "/Users/shanmuganathans/opt/anaconda3/lib/python3.9/site-packages/django/shortcuts.py", line 24, in render
    content = loader.render_to_string(template_name, context, request, using=using)
  File "/Users/shanmuganathans/opt/anaconda3/lib/python3.9/site-packages/django/template/loader.py", line 61, in render_to_string
    template = get_template(template_name, using=using)
  File "/Users/shanmuganathans/opt/anaconda3/lib/python3.9/site-packages/django/template/loader.py", line 19, in get_template
    raise TemplateDoesNotExist(template_name, chain=chain)
django.template.exceptions.TemplateDoesNotExist: blog/pagination.html
WARNING 2024-03-27 16:38:19,817 log Not Found: /blog/
